<?xml version="1.0"?>
<robot xmlns:xacro="http://www.ros.org/wiki/xacro">

    <xacro:include filename="inertial_macros.xacro" />

    <!-- we'll define colors to use later-->
    <material name="white">
        <color rgba="1 1 1 1"/>
    </material>
    
    <material name="black">
        <color rgba="0 0 0 1"/>
    </material>

    <material name="orange">
        <color rgba="1 0.3 0.1 1"/>
    </material>

    <material name="blue">
        <color rgba="0.2 0.2 1 1"/>
    </material>

    <!-- It's common in ROS to define BASE_LINK first. We define it in the center of the wheel connection, and define the rest of the body in terms of that location -->
    <!-- BASE_LINK -->

    <link name="base_link">
    </link>

    <!-- CHASSIS LINK -->
    <!-- Joint links parent to child link, where we can define the origin location offset - in this case it'll be 0.1m behind the center of the wheel connection. -->
    <joint name="chassis_joint" type="fixed">
        <parent link="base_link"/>
        <child link="chassis"/>
        <origin xyz="0 0 0"/>
    </joint>

    <!-- Now we'll create the actual chassis link -->
    <link name="chassis">
        <visual>
        <!-- The geometry will center in joint origin. We want to align it to the wheel connector -->
            <origin xyz="0 0 0.0625"/>
            <geometry>
                <cylinder radius="0.08" length="0.125"/>
            </geometry>
            <material name="blue"/>
        </visual>
        <collision>
        <!-- The geometry will center in joint origin. We want to align it to the wheel connector -->
            <origin xyz="0 0 0.0625"/>
            <geometry>
                <cylinder radius="0.08" length="0.125"/>
            </geometry>
        </collision>
        <xacro:inertial_cylinder mass="2.0" length="0.125" radius="0.08">
            <origin xyz="0 0 0.0625" rpy="0 0 0"/>
        </xacro:inertial_cylinder>
    </link>

    <!-- LEFT WHEEL LINK -->
    <joint name="left_wheel_joint" type="continuous">
        <parent link="base_link"/>
        <child link="left_wheel"/>
        <origin xyz="0 0.08 0" rpy="-${pi/2} 0 0"/>
        <axis xyz="0 0 1"/>
    </joint>


    <link name="left_wheel">
        <visual>
            <geometry>
                <cylinder radius="0.0325" length="0.02"/>
                <material name="black"/>
            </geometry>
        </visual>
        <collision>
            <geometry>
                <cylinder radius="0.0325" length="0.02"/>
            </geometry>
        </collision>
        <xacro:inertial_cylinder mass="0.5" length="0.02" radius="0.0325">
            <origin xyz="0 0 0" rpy="0 0 0"/>
        </xacro:inertial_cylinder>
    </link>

    <!-- RIGHT WHEEL LINK -->
    <joint name="right_wheel_joint" type="continuous">
        <parent link="base_link"/>
        <child link="right_wheel"/>
        <origin xyz="0 -0.08 0" rpy="${pi/2} 0 0"/>
        <axis xyz="0 0 -1"/>
    </joint>

    <link name="right_wheel">
        <visual>
            <geometry>
                <cylinder radius="0.0325" length="0.02"/>
                <material name="black"/>
            </geometry>
        </visual>
        <collision>
            <geometry>
                <cylinder radius="0.0325" length="0.02"/>
            </geometry>
        </collision>
        <xacro:inertial_cylinder mass="0.5" length="0.02" radius="0.0325">
            <origin xyz="0 0 0" rpy="0 0 0"/>
        </xacro:inertial_cylinder>
    </link>


    <!-- Front Caster Wheel Link -->
    <joint name="front_caster_wheel_joint" type="fixed">
        <parent link="chassis"/>
        <child link="front_caster_wheel"/>
        <origin xyz="0.07 0 0"/>
    </joint>

    <link name="front_caster_wheel">
        <visual>
            <geometry>
                <sphere radius="0.0325"/>
            </geometry>
            <material name="black"/>
        </visual>
        <collision>
            <geometry>
                <sphere radius="0.0325"/>
            </geometry>
        </collision>
        <xacro:inertial_sphere mass="0.5" radius="0.0325">
            <origin xyz="0 0 0" rpy="0 0 0"/>
        </xacro:inertial_sphere>
    </link>

    <gazebo reference="front_caster_wheel">
        <material>Gazebo/Black</material>
        <mu1 value="0.001"/>
        <mu2 value="0.001"/>
    </gazebo>

    <!-- Back Caster Wheel Link -->
    <joint name="back_caster_wheel_joint" type="fixed">
        <parent link="chassis"/>
        <child link="back_caster_wheel"/>
        <origin xyz="-0.07 0 0"/>
    </joint>

    <link name="back_caster_wheel">
        <visual>
            <geometry>
                <sphere radius="0.0325"/>
            </geometry>
            <material name="black"/>
        </visual>
        <collision>
            <geometry>
                <sphere radius="0.0325"/>
            </geometry>
        </collision>
        <xacro:inertial_sphere mass="0.5" radius="0.0325">
            <origin xyz="0 0 0" rpy="0 0 0"/>
        </xacro:inertial_sphere>
    </link>

    <gazebo reference="back_caster_wheel">
        <material>Gazebo/Black</material>
        <mu1 value="0.001"/>
        <mu2 value="0.001"/>
    </gazebo>

</robot>